Workbook

Sheet FiveParts
D1: Fitted Model
A2: Code | B2: RDA | C2: Comps. | D2: 1 | E2: 2 | F2: 3 | G2: 4 | H2: 5 | I2: 6 | J2: 7 | K2: 8 | L2: 9 | M2: 10 | N2: 11 | O2: 12 | P2: 13 | Q2: 14 | R2: 15 | S2: 16 | T2: 17 | U2: 18 | V2: 19 | W2: 20 | X2: 21 | Y2: 22 | Z2: 23 | AA2: 24 | AB2: 25 | AC2: 26 | AD2: 27 | AE2: 28 | AF2: 29 | AG2: 30 | AH2: 31 | AL2: Fraction | AM2: Partition | AN2: Shortform | AO2: Longform | AQ2: Intermediary | AR2: Formula | AS2: Subtraction
A3: 1 | B3: A1 | C3: X1 | D3: X | I3: X | J3: X | K3: X | L3: X | S3: X | T3: X | U3: X | V3: X | W3: X | X3: X | AC3: X | AD3: X | AE3: X | AF3: X | AH3: X | AI3: =COUNTIF(D3:AH3,"X") -> 16 | AL3: B1 | AM3: X1 Only | AN3: A31 - A30 | AO3: A31 - A30
A4: 2 | B4: A2 | C4: X2 | E4: X | I4: X | M4: X | N4: X | O4: X | S4: X | T4: X | U4: X | Y4: X | Z4: X | AA4: X | AC4: X | AD4: X | AE4: X | AG4: X | AH4: X | AI4: =COUNTIF(D4:AH4,"X") -> 16 | AL4: B2 | AM4: X2 Only | AN4: A31 - A29 | AO4: A31 - A29
A5: 3 | B5: A3 | C5: X3 | F5: X | J5: X | M5: X | P5: X | Q5: X | S5: X | V5: X | W5: X | Y5: X | Z5: X | AB5: X | AC5: X | AD5: X | AF5: X | AG5: X | AH5: X | AI5: =COUNTIF(D5:AH5,"X") -> 16 | AL5: B3 | AM5: X3 Only | AN5: A31 - A28 | AO5: A31 - A28
A6: 4 | B6: A4 | C6: X4 | G6: X | K6: X | N6: X | P6: X | R6: X | T6: X | V6: X | X6: X | Y6: X | AA6: X | AB6: X | AC6: X | AE6: X | AF6: X | AG6: X | AH6: X | AI6: =COUNTIF(D6:AH6,"X") -> 16 | AL6: B4 | AM6: X4 Only | AN6: A31 - A27 | AO6: A31 - A27
A7: 5 | B7: A5 | C7: X5 | H7: X | L7: X | O7: X | Q7: X | R7: X | U7: X | W7: X | X7: X | Z7: X | AA7: X | AB7: X | AD7: X | AE7: X | AF7: X | AG7: X | AH7: X | AI7: =COUNTIF(D7:AH7,"X") -> 16 | AL7: B5 | AM7: X5 Only | AN7: A31 - A26 | AO7: A31 - A26
A8: 1,2 | B8: A6 | C8: X1,X2 | D8: X | E8: X | I8: X | J8: X | K8: X | L8: X | M8: X | N8: X | O8: X | S8: X | T8: X | U8: X | V8: X | W8: X | X8: X | Y8: X | Z8: X | AA8: X | AC8: X | AD8: X | AE8: X | AF8: X | AG8: X | AH8: X | AI8: =COUNTIF(D8:AH8,"X") -> 24 | AL8: B6 | AM8: X1 and X2 | AN8: I1 - A1 | AO8: A29 - A25 - A1 | AQ8: I1 | AR8: 1+6 | AS8: A29 - A25
A9: 1,3 | B9: A7 | C9: X1,X3 | D9: X | F9: X | I9: X | J9: X | K9: X | L9: X | M9: X | P9: X | Q9: X | S9: X | T9: X | U9: X | V9: X | W9: X | X9: X | Y9: X | Z9: X | AB9: X | AC9: X | AD9: X | AE9: X | AF9: X | AG9: X | AH9: X | AI9: =COUNTIF(D9:AH9,"X") -> 24 | AL9: B7 | AM9: X1 and X3 | AN9: I2 - A1 | AO9: A28 - A24 - A1 | AQ9: I2 | AR9: 1+7 | AS9: A28 - A24
A10: 1,4 | B10: A8 | C10: X1,X4 | D10: X | G10: X | I10: X | J10: X | K10: X | L10: X | N10: X | P10: X | R10: X | S10: X | T10: X | U10: X | V10: X | W10: X | X10: X | Y10: X | AA10: X | AB10: X | AC10: X | AD10: X | AE10: X | AF10: X | AG10: X | AH10: X | AI10: =COUNTIF(D10:AH10,"X") -> 24 | AL10: B8 | AM10: X1 and X4 | AN10: I3 - A1 | AO10: A27 - A23 - A1 | AQ10: I3 | AR10: 1+8 | AS10: A27 - A23
A11: 1,5 | B11: A9 | C11: X1,X5 | D11: X | H11: X | I11: X | J11: X | K11: X | L11: X | O11: X | Q11: X | R11: X | S11: X | T11: X | U11: X | V11: X | W11: X | X11: X | Z11: X | AA11: X | AB11: X | AC11: X | AD11: X | AE11: X | AF11: X | AG11: X | AH11: X | AI11: =COUNTIF(D11:AH11,"X") -> 24 | AL11: B9 | AM11: X1 and X5 | AN11: I4 - A1 | AO11: A26 - A22 - A1 | AQ11: I4 | AR11: 1+9 | AS11: A26 - A22
A12: 2,3 | B12: A10 | C12: X2,X3 | E12: X | F12: X | I12: X | J12: X | M12: X | N12: X | O12: X | P12: X | Q12: X | S12: X | T12: X | U12: X | V12: X | W12: X | Y12: X | Z12: X | AA12: X | AB12: X | AC12: X | AD12: X | AE12: X | AF12: X | AG12: X | AH12: X | AI12: =COUNTIF(D12:AH12,"X") -> 24 | AL12: B10 | AM12: X2 and X3 | AN12: I5 - A2 | AO12: A28 - A21 - A2 | AQ12: I5 | AR12: 2+10 | AS12: A28 - A21
A13: 2,4 | B13: A11 | C13: X2,X4 | E13: X | G13: X | I13: X | K13: X | M13: X | N13: X | O13: X | P13: X | R13: X | S13: X | T13: X | U13: X | V13: X | X13: X | Y13: X | Z13: X | AA13: X | AB13: X | AC13: X | AD13: X | AE13: X | AF13: X | AG13: X | AH13: X | AI13: =COUNTIF(D13:AH13,"X") -> 24 | AL13: B11 | AM13: X2 and X4 | AN13: I6 - A2 | AO13: A27 - A20 - A2 | AQ13: I6 | AR13: 2+11 | AS13: A27 - A20
A14: 2,5 | B14: A12 | C14: X2,X5 | E14: X | H14: X | I14: X | L14: X | M14: X | N14: X | O14: X | Q14: X | R14: X | S14: X | T14: X | U14: X | W14: X | X14: X | Y14: X | Z14: X | AA14: X | AB14: X | AC14: X | AD14: X | AE14: X | AF14: X | AG14: X | AH14: X | AI14: =COUNTIF(D14:AH14,"X") -> 24 | AL14: B12 | AM14: X2 and X5 | AN14: I7 - A2 | AO14: A26 - A19 - A2 | AQ14: I7 | AR14: 2+12 | AS14: A26 - A19
A15: 3,4 | B15: A13 | C15: X3,X4 | F15: X | G15: X | J15: X | K15: X | M15: X | N15: X | P15: X | Q15: X | R15: X | S15: X | T15: X | V15: X | W15: X | X15: X | Y15: X | Z15: X | AA15: X | AB15: X | AC15: X | AD15: X | AE15: X | AF15: X | AG15: X | AH15: X | AI15: =COUNTIF(D15:AH15,"X") -> 24 | AL15: B13 | AM15: X3 and X4 | AN15: I8 - A3 | AO15: A27 - A18 - A3 | AQ15: I8 | AR15: 3+13 | AS15: A27 - A18
A16: 3,5 | B16: A14 | C16: X3,X5 | F16: X | H16: X | J16: X | L16: X | M16: X | O16: X | P16: X | Q16: X | R16: X | S16: X | U16: X | V16: X | W16: X | X16: X | Y16: X | Z16: X | AA16: X | AB16: X | AC16: X | AD16: X | AE16: X | AF16: X | AG16: X | AH16: X | AI16: =COUNTIF(D16:AH16,"X") -> 24 | AL16: B14 | AM16: X3 and X5 | AN16: I9 - A3 | AO16: A26 - A17 - A3 | AQ16: I9 | AR16: 3+14 | AS16: A26 - A17
A17: 4,5 | B17: A15 | C17: X4,X5 | G17: X | H17: X | K17: X | L17: X | N17: X | O17: X | P17: X | Q17: X | R17: X | T17: X | U17: X | V17: X | W17: X | X17: X | Y17: X | Z17: X | AA17: X | AB17: X | AC17: X | AD17: X | AE17: X | AF17: X | AG17: X | AH17: X | AI17: =COUNTIF(D17:AH17,"X") -> 24 | AL17: B15 | AM17: X4 and X5 | AN17: I10 - A4 | AO17: A26 - A16 - A4 | AQ17: I10 | AR17: 4+15 | AS17: A26 - A16
A18: 1,2,3 | B18: A16 | C18: X1,X2,X3 | D18: X | E18: X | F18: X | I18: X | J18: X | K18: X | L18: X | M18: X | N18: X | O18: X | P18: X | Q18: X | S18: X | T18: X | U18: X | V18: X | W18: X | X18: X | Y18: X | Z18: X | AA18: X | AB18: X | AC18: X | AD18: X | AE18: X | AF18: X | AG18: X | AH18: X | AI18: =COUNTIF(D18:AH18,"X") -> 28 | AL18: B16 | AM18: X1, X2, X3 | AN18: I11 - I1 - B7 | AO18: (A21 - A15) - (A29 - A25) - (A28 - A24 - A1) | AQ18: I11 | AR18: 1+6+7+16 | AS18: A21 - A15
A19: 1,2,4 | B19: A17 | C19: X1,X2,X4 | D19: X | E19: X | G19: X | I19: X | J19: X | K19: X | L19: X | M19: X | N19: X | O19: X | P19: X | R19: X | S19: X | T19: X | U19: X | V19: X | W19: X | X19: X | Y19: X | Z19: X | AA19: X | AB19: X | AC19: X | AD19: X | AE19: X | AF19: X | AG19: X | AH19: X | AI19: =COUNTIF(D19:AH19,"X") -> 28 | AL19: B17 | AM19: X1, X2, X4 | AN19: I12 - I1 - B8 | AO19: (A20 - A14) - (A29 - A25) - (A27 - A23 - A1) | AQ19: I12 | AR19: 1+6+8+17 | AS19: A20 - A14
A20: 1,2,5 | B20: A18 | C20: X1,X2,X5 | D20: X | E20: X | H20: X | I20: X | J20: X | K20: X | L20: X | M20: X | N20: X | O20: X | Q20: X | R20: X | S20: X | T20: X | U20: X | V20: X | W20: X | X20: X | Y20: X | Z20: X | AA20: X | AB20: X | AC20: X | AD20: X | AE20: X | AF20: X | AG20: X | AH20: X | AI20: =COUNTIF(D20:AH20,"X") -> 28 | AL20: B18 | AM20: X1, X2, X5 | AN20: I13 - I1 - B9 | AO20: (A19 - A13) - (A29 - A25) - (A26 - A22 - A1) | AQ20: I13 | AR20: 1+6+9+18 | AS20: A19 - A13
A21: 1,3,4 | B21: A19 | C21: X1,X3,X4 | D21: X | F21: X | G21: X | I21: X | J21: X | K21: X | L21: X | M21: X | N21: X | P21: X | Q21: X | R21: X | S21: X | T21: X | U21: X | V21: X | W21: X | X21: X | Y21: X | Z21: X | AA21: X | AB21: X | AC21: X | AD21: X | AE21: X | AF21: X | AG21: X | AH21: X | AI21: =COUNTIF(D21:AH21,"X") -> 28 | AL21: B19 | AM21: X1, X3, X4 | AN21: I14 - I2 - B8 | AO21: (A18 - A12) - (A28 - A24) - (A27 - A23 - A1) | AQ21: I14 | AR21: 1+7+8+19 | AS21: A18 - A12
A22: 1,3,5 | B22: A20 | C22: X1,X3,X5 | D22: X | F22: X | H22: X | I22: X | J22: X | K22: X | L22: X | M22: X | O22: X | P22: X | Q22: X | R22: X | S22: X | T22: X | U22: X | V22: X | W22: X | X22: X | Y22: X | Z22: X | AA22: X | AB22: X | AC22: X | AD22: X | AE22: X | AF22: X | AG22: X | AH22: X | AI22: =COUNTIF(D22:AH22,"X") -> 28 | AL22: B20 | AM22: X1, X3, X5 | AN22: I15 - I2 - B9 | AO22: (A17 - A11) - (A28 - A24) - (A26 - A22 - A1) | AQ22: I15 | AR22: 1+7+9+20 | AS22: A17 - A11
A23: 1,4,5 | B23: A21 | C23: X1,X4,X5 | D23: X | G23: X | H23: X | I23: X | J23: X | K23: X | L23: X | N23: X | O23: X | P23: X | Q23: X | R23: X | S23: X | T23: X | U23: X | V23: X | W23: X | X23: X | Y23: X | Z23: X | AA23: X | AB23: X | AC23: X | AD23: X | AE23: X | AF23: X | AG23: X | AH23: X | AI23: =COUNTIF(D23:AH23,"X") -> 28 | AL23: B21 | AM23: X1, X4, X5 | AN23: I16 - I3 - B9 | AO23: (A16 - A10) - (A27 - A23) - (A26 - A22 - A1) | AQ23: I16 | AR23: 1+8+9+21 | AS23: A16 - A10
A24: 2,3,4 | B24: A22 | C24: X2,X3,X4 | E24: X | F24: X | G24: X | I24: X | J24: X | K24: X | M24: X | N24: X | O24: X | P24: X | Q24: X | R24: X | S24: X | T24: X | U24: X | V24: X | W24: X | X24: X | Y24: X | Z24: X | AA24: X | AB24: X | AC24: X | AD24: X | AE24: X | AF24: X | AG24: X | AH24: X | AI24: =COUNTIF(D24:AH24,"X") -> 28 | AL24: B22 | AM24: X2, X3, X4 | AN24: I17 - I5 - B11 | AO24: (A18 - A9) - (A28 - A21) - (A27 - A20 - A2) | AQ24: I17 | AR24: 2+10+11+22 | AS24: A18 - A9
A25: 2,3,5 | B25: A23 | C25: X2,X3,X5 | E25: X | F25: X | H25: X | I25: X | J25: X | L25: X | M25: X | N25: X | O25: X | P25: X | Q25: X | R25: X | S25: X | T25: X | U25: X | V25: X | W25: X | X25: X | Y25: X | Z25: X | AA25: X | AB25: X | AC25: X | AD25: X | AE25: X | AF25: X | AG25: X | AH25: X | AI25: =COUNTIF(D25:AH25,"X") -> 28 | AL25: B23 | AM25: X2, X3, X5 | AN25: I18 - I5 - B12 | AO25: (A17 - A8) - (A28 - A21) - (A26 - A19 - A2) | AQ25: I18 | AR25: 2+10+12+23 | AS25: A17 - A8
A26: 2,4,5 | B26: A24 | C26: X2,X4,X5 | E26: X | G26: X | H26: X | I26: X | K26: X | L26: X | M26: X | N26: X | O26: X | P26: X | Q26: X | R26: X | S26: X | T26: X | U26: X | V26: X | W26: X | X26: X | Y26: X | Z26: X | AA26: X | AB26: X | AC26: X | AD26: X | AE26: X | AF26: X | AG26: X | AH26: X | AI26: =COUNTIF(D26:AH26,"X") -> 28 | AL26: B24 | AM26: X2, X4, X5 | AN26: I19 - I6 - B12 | AO26: (A16 - A7) - (A27 - A20) - (A26 - A19 - A2) | AQ26: I19 | AR26: 2+11+12+24 | AS26: A16 - A7
A27: 3,4,5 | B27: A25 | C27: X3,X4,X5 | F27: X | G27: X | H27: X | J27: X | K27: X | L27: X | M27: X | N27: X | O27: X | P27: X | Q27: X | R27: X | S27: X | T27: X | U27: X | V27: X | W27: X | X27: X | Y27: X | Z27: X | AA27: X | AB27: X | AC27: X | AD27: X | AE27: X | AF27: X | AG27: X | AH27: X | AI27: =COUNTIF(D27:AH27,"X") -> 28 | AL27: B25 | AM27: X3, X4, X5 | AN27: I20 - I8 - B14 | AO27: (A16 - A6) - (A27 - A18) - (A26 - A17 - A3) | AQ27: I20 | AR27: 3+13+14+25 | AS27: A16 - A6
A28: 1,2,3,4 | B28: A26 | C28: X1,X2,X3,X4 | D28: X | E28: X | F28: X | G28: X | I28: X | J28: X | K28: X | L28: X | M28: X | N28: X | O28: X | P28: X | Q28: X | R28: X | S28: X | T28: X | U28: X | V28: X | W28: X | X28: X | Y28: X | Z28: X | AA28: X | AB28: X | AC28: X | AD28: X | AE28: X | AF28: X | AG28: X | AH28: X | AI28: =COUNTIF(D28:AH28,"X") -> 30 | AL28: B26 | AM28: X1, X2, X3, X4 | AN28: I21 - I11 - B8 - B17 - B19 | AO28: (A9 - A5) - (A21 - A15) - (A27 - A23 - A1) - [(A20 - A14) - (A29 - A25) - (A27 - A23 - A1)] - [(A18 - A12) - (A28 - A24) - (A27 - A23 - A1)] | AQ28: I21 | AR28: 1+6+7+8+16+17+19+26 | AS28: A9 - A5
A29: 1,2,3,5 | B29: A27 | C29: X1,X2,X3,X5 | D29: X | E29: X | F29: X | H29: X | I29: X | J29: X | K29: X | L29: X | M29: X | N29: X | O29: X | P29: X | Q29: X | R29: X | S29: X | T29: X | U29: X | V29: X | W29: X | X29: X | Y29: X | Z29: X | AA29: X | AB29: X | AC29: X | AD29: X | AE29: X | AF29: X | AG29: X | AH29: X | AI29: =COUNTIF(D29:AH29,"X") -> 30 | AL29: B27 | AM29: X1, X2, X3, X5 | AN29: I22 - I11 - B9 - B18 - B20 | AO29: (A8 - A4) - (A21 - A15) - (A26 - A22 - A1) - [(A19 - A13) - (A29 - A25) - (A26 - A22 - A1)] - [(A17 - A11) - (A28 - A24) - (A26 - A22 - A1)] | AQ29: I22 | AR29: 1+6+7+9+16+18+20+27 | AS29: A8 - A4
A30: 1,2,4,5 | B30: A28 | C30: X1,X2,X4,X5 | D30: X | E30: X | G30: X | H30: X | I30: X | J30: X | K30: X | L30: X | M30: X | N30: X | O30: X | P30: X | Q30: X | R30: X | S30: X | T30: X | U30: X | V30: X | W30: X | X30: X | Y30: X | Z30: X | AA30: X | AB30: X | AC30: X | AD30: X | AE30: X | AF30: X | AG30: X | AH30: X | AI30: =COUNTIF(D30:AH30,"X") -> 30 | AL30: B28 | AM30: X1, X2, X4, X5 | AN30: I23 - I12 - B9 - B18 - B21 | AO30: (A7 - A3) - (A20 - A14) - (A26 - A22 - A1) - [(A19 - A13) - (A29 - A25) - (A26 - A22 - A1)] - [(A16 - A10) - (A27 - A23) - (A26 - A22 - A1)] | AQ30: I23 | AR30: 1+6+8+9+17+18+21+28 | AS30: A7 - A3
A31: 1,3,4,5 | B31: A29 | C31: X1,X3,X4,X5 | D31: X | F31: X | G31: X | H31: X | I31: X | J31: X | K31: X | L31: X | M31: X | N31: X | O31: X | P31: X | Q31: X | R31: X | S31: X | T31: X | U31: X | V31: X | W31: X | X31: X | Y31: X | Z31: X | AA31: X | AB31: X | AC31: X | AD31: X | AE31: X | AF31: X | AG31: X | AH31: X | AI31: =COUNTIF(D31:AH31,"X") -> 30 | AL31: B29 | AM31: X1, X3, X4, X5 | AN31: I24 - I14 - B9 - B20 - B21 | AO31: (A6 - A2) - (A18 - A12) - (A26 - A22 - A1) - [(A17 - A11) - (A28 - A24) - (A27 - A23 - A1)] - [(A16 - A10) - (A27 - A23) - (A26 - A22 - A1)] | AQ31: I24 | AR31: 1+7+8+9+19+20+21+29 | AS31: A6 - A2
A32: 2,3,4,5 | B32: A30 | C32: X2,X3,X4,X5 | E32: X | F32: X | G32: X | H32: X | I32: X | J32: X | K32: X | L32: X | M32: X | N32: X | O32: X | P32: X | Q32: X | R32: X | S32: X | T32: X | U32: X | V32: X | W32: X | X32: X | Y32: X | Z32: X | AA32: X | AB32: X | AC32: X | AD32: X | AE32: X | AF32: X | AG32: X | AH32: X | AI32: =COUNTIF(D32:AH32,"X") -> 30 | AL32: B30 | AM32: X2, X3, X4, X5 | AN32: I25 - I17 - B12 - B23 - B24 | AO32: (A6 - A1) - (A18 - A9) - (A26 - A19 - A2) - [(A17 - A8) - (A28 - A21) - (A26 - A19 - A2)] - [(A16 - A7) - (A27 - A20) - (A26 - A19 - A2)] | AQ32: I25 | AR32: 2+10+11+12+22+23+24+30 | AS32: A6 - A1
A33: 1,2,3,4,5 | B33: A31 | C33: X1,X2,X3,X4,X5 | D33: X | E33: X | F33: X | G33: X | H33: X | I33: X | J33: X | K33: X | L33: X | M33: X | N33: X | O33: X | P33: X | Q33: X | R33: X | S33: X | T33: X | U33: X | V33: X | W33: X | X33: X | Y33: X | Z33: X | AA33: X | AB33: X | AC33: X | AD33: X | AE33: X | AF33: X | AG33: X | AH33: X | AI33: =COUNTIF(D33:AH33,"X") -> 31 | AL33: B31 | AM33: X1, X2, X3, X4, X5 | AN33: A1 - I11 - B8 - B9 - B17 - B18 - B19 - B20 - B21 - B26 - B27 - B28 - B29 | AO33: A1 - (A21 - A15) - (A27 - A23 - A1) - (A26 - A22 - A1) - [(A20 - A14) - (A29 - A25) - (A27 - A23 - A1)] - [(A19 - A13) - (A29 - A25) - (A26 - A22 - A1)] - [(A18 - A12) - (A28 - A24) - (A27 - A23 - A1)] - [(A17 - A11) - (A28 - A24) - (A26 - A22 - A1)] - [(A16 - A10) - (A27 - A23) - (A26 - A22 - A1)] - {(A9 - A5) - (A21 - A15) - (A27 - A23 - A1) - [(A20 - A14) - (A29 - A25) - (A27 - A23 - A1)] - [(A18 - A12) - (A28 - A24) - (A27 - A23 - A1)]} - {(A8 - A4) - (A21 - A15) - (A26 - A22 - A1) - [(A19 - A13) - (A29 - A25) - (A26 - A22 - A1)] - [(A17 - A11) - (A28 - A24) - (A26 - A22 - A1)]} - {(A7 - A3) - (A20 - A14) - (A26 - A22 - A1) - [(A19 - A13) - (A29 - A25) - (A26 - A22 - A1)] - [(A16 - A10) - (A27 - A23) - (A26 - A22 - A1)]} - {(A6 - A2) - (A18 - A12) - (A26 - A22 - A1) - [(A17 - A11) - (A28 - A24) - (A27 - A23 - A1)] - [(A16 - A10) - (A27 - A23) - (A26 - A22 - A1)]} | AQ33: I26

Sheet Results_cor
A1: Response | B1: AdjustedR2 | C1: R2 | D1: RSS | E1: No.Groups | F1: Selections | G1: RDA
A2: Total | B2: 0.30639 | C2: 0.32644 | D2: 399980 | E2: 1 | F2: 4 | G2: =VLOOKUP($F2,FiveParts!$A$3:$B$33,2,FALSE) -> A4
A3: Total | B3: 0.17081 | C3: 0.1804 | D3: 486710 | E3: 1 | F3: 1 | G3: =VLOOKUP($F3,FiveParts!$A$3:$B$33,2,FALSE) -> A1
A4: Total | B4: 0.11939 | C4: 0.12957 | D4: 516890 | E4: 1 | F4: 3 | G4: =VLOOKUP($F4,FiveParts!$A$3:$B$33,2,FALSE) -> A3
A5: Total | B5: 0.10215 | C5: 0.11253 | D5: 527010 | E5: 1 | F5: 2 | G5: =VLOOKUP($F5,FiveParts!$A$3:$B$33,2,FALSE) -> A2
A6: Total | B6: 0.040396 | C6: 0.048716 | D6: 564900 | E6: 1 | F6: 5 | G6: =VLOOKUP($F6,FiveParts!$A$3:$B$33,2,FALSE) -> A5
A7: Total | B7: 0.4075 | C7: 0.43148 | D7: 337610 | E7: 2 | F7: 3,4 | G7: =VLOOKUP($F7,FiveParts!$A$3:$B$33,2,FALSE) -> A13
A8: Total | B8: 0.40461 | C8: 0.4287 | D8: 339260 | E8: 2 | F8: 1,4 | G8: =VLOOKUP($F8,FiveParts!$A$3:$B$33,2,FALSE) -> A8
A9: Total | B9: 0.39854 | C9: 0.42287 | D9: 342720 | E9: 2 | F9: 2,4 | G9: =VLOOKUP($F9,FiveParts!$A$3:$B$33,2,FALSE) -> A11
A10: Total | B10: 0.34249 | C10: 0.3672 | D10: 375780 | E10: 2 | F10: 4,5 | G10: =VLOOKUP($F10,FiveParts!$A$3:$B$33,2,FALSE) -> A15
A11: Total | B11: 0.30761 | C11: 0.32362 | D11: 401660 | E11: 2 | F11: 1,3 | G11: =VLOOKUP($F11,FiveParts!$A$3:$B$33,2,FALSE) -> A7
A12: Total | B12: 0.27195 | C12: 0.28879 | D12: 422340 | E12: 2 | F12: 1,2 | G12: =VLOOKUP($F12,FiveParts!$A$3:$B$33,2,FALSE) -> A6
A13: Total | B13: 0.23213 | C13: 0.24988 | D13: 445440 | E13: 2 | F13: 2,3 | G13: =VLOOKUP($F13,FiveParts!$A$3:$B$33,2,FALSE) -> A10
A14: Total | B14: 0.2058 | C14: 0.22187 | D14: 462080 | E14: 2 | F14: 1,5 | G14: =VLOOKUP($F14,FiveParts!$A$3:$B$33,2,FALSE) -> A9
A15: Total | B15: 0.14326 | C15: 0.1606 | D15: 498470 | E15: 2 | F15: 3,5 | G15: =VLOOKUP($F15,FiveParts!$A$3:$B$33,2,FALSE) -> A14
A16: Total | B16: 0.14075 | C16: 0.15813 | D16: 499930 | E16: 2 | F16: 2,5 | G16: =VLOOKUP($F16,FiveParts!$A$3:$B$33,2,FALSE) -> A12
A17: Total | B17: 0.45414 | C17: 0.48254 | D17: 307290 | E17: 3 | F17: 2,3,4 | G17: =VLOOKUP($F17,FiveParts!$A$3:$B$33,2,FALSE) -> A22
A18: Total | B18: 0.44981 | C18: 0.47843 | D18: 309720 | E18: 3 | F18: 1,3,4 | G18: =VLOOKUP($F18,FiveParts!$A$3:$B$33,2,FALSE) -> A19
... A32: Total | B32: 0.48231 | C32: 0.51822 | D32: 286100 | E32: 5 | F32: 1,2,3,4,5 | G32: =VLOOKUP($F32,FiveParts!$A$3:$B$33,2,FALSE) -> A31
A33: Success | B33: 0.234 | C33: 0.25653 | D33: 514550 | E33: 1 | F33: 4 | G33: =VLOOKUP($F33,FiveParts!$A$3:$B$33,2,FALSE) -> A4
A34: Success | B34: 0.1357 | C34: 0.147 | D34: 590360 | E34: 1 | F34: 1 | G34: =VLOOKUP($F34,FiveParts!$A$3:$B$33,2,FALSE) -> A1
A35: Success | B35: 0.087974 | C35: 0.10586 | D35: 618840 | E35: 1 | F35: 3 | G35: =VLOOKUP($F35,FiveParts!$A$3:$B$33,2,FALSE) -> A3
A36: Success | B36: 0.079055 | C36: 0.091093 | D36: 629050 | E36: 1 | F36: 2 | G36: =VLOOKUP($F36,FiveParts!$A$3:$B$33,2,FALSE) -> A2
A37: Success | B37: 0.052549 | C37: 0.06803 | D37: 645010 | E37: 1 | F37: 5 | G37: =VLOOKUP($F37,FiveParts!$A$3:$B$33,2,FALSE) -> A5
A38: Success | B38: 0.319 | C38: 0.34793 | D38: 451300 | E38: 2 | F38: 1,4 | G38: =VLOOKUP($F38,FiveParts!$A$3:$B$33,2,FALSE) -> A8
A39: Success | B39: 0.31499 | C39: 0.34857 | D39: 450860 | E39: 2 | F39: 3,4 | G39: =VLOOKUP($F39,FiveParts!$A$3:$B$33,2,FALSE) -> A13
A40: Success | B40: 0.31475 | C40: 0.34386 | D40: 454120 | E40: 2 | F40: 2,4 | G40: =VLOOKUP($F40,FiveParts!$A$3:$B$33,2,FALSE) -> A11
A41: Success | B41: 0.27483 | C41: 0.30801 | D41: 478930 | E41: 2 | F41: 4,5 | G41: =VLOOKUP($F41,FiveParts!$A$3:$B$33,2,FALSE) -> A15
A42: Success | B42: 0.25221 | C42: 0.27665 | D42: 500630 | E42: 2 | F42: 1,3 | G42: =VLOOKUP($F42,FiveParts!$A$3:$B$33,2,FALSE) -> A7
A43: Success | B43: 0.21243 | C43: 0.23302 | D43: 530820 | E43: 2 | F43: 1,2 | G43: =VLOOKUP($F43,FiveParts!$A$3:$B$33,2,FALSE) -> A6
A44: Success | B44: 0.19656 | C44: 0.22282 | D44: 537880 | E44: 2 | F44: 2,3 | G44: =VLOOKUP($F44,FiveParts!$A$3:$B$33,2,FALSE) -> A10
A45: Success | B45: 0.17805 | C45: 0.20223 | D45: 552140 | E45: 2 | F45: 1,5 | G45: =VLOOKUP($F45,FiveParts!$A$3:$B$33,2,FALSE) -> A9
A46: Success | B46: 0.13106 | C46: 0.15662 | D46: 583700 | E46: 2 | F46: 2,5 | G46: =VLOOKUP($F46,FiveParts!$A$3:$B$33,2,FALSE) -> A12
A47: Success | B47: 0.12386 | C47: 0.15536 | D47: 584570 | E47: 2 | F47: 3,5 | G47: =VLOOKUP($F47,FiveParts!$A$3:$B$33,2,FALSE) -> A14
A48: Success | B48: 0.3711 | C48: 0.40604 | D48: 411080 | E48: 3 | F48: 1,2,4 | G48: =VLOOKUP($F48,FiveParts!$A$3:$B$33,2,FALSE) -> A17
A49: Success | B49: 0.36666 | C49: 0.40598 | D49: 411120 | E49: 3 | F49: 1,3,4 | G49: =VLOOKUP($F49,FiveParts!$A$3:$B$33,2,FALSE) -> A19
... A63: Success | B63: 0.4437 | C63: 0.4946 | D63: 349790 | E63: 5 | F63: 1,2,3,4,5 | G63: =VLOOKUP($F63,FiveParts!$A$3:$B$33,2,FALSE) -> A31
A64: Failure | B64: 0.17604 | C64: 0.19489 | D64: 573420 | E64: 1 | F64: 4 | G64: =VLOOKUP($F64,FiveParts!$A$3:$B$33,2,FALSE) -> A4
A65: Failure | B65: 0.14596 | C65: 0.15713 | D65: 600320 | E65: 1 | F65: 1 | G65: =VLOOKUP($F65,FiveParts!$A$3:$B$33,2,FALSE) -> A1
A66: Failure | B66: 0.058411 | C66: 0.070719 | D66: 661860 | E66: 1 | F66: 2 | G66: =VLOOKUP($F66,FiveParts!$A$3:$B$33,2,FALSE) -> A2
...

Sheet Results_nocor
A1: Response | B1: AdjustedR2 | C1: R2 | D1: RSS | E1: No.Groups | F1: Selections | G1: RDA
A2: Total | B2: 0.17081 | C2: 0.1804 | D2: 486710 | E2: 1 | F2: 3 | G2: =VLOOKUP($F2,FiveParts!$A$3:$B$33,2,FALSE) -> A3
A3: Total | B3: 0.11939 | C3: 0.12957 | D3: 516890 | E3: 1 | F3: 5 | G3: =VLOOKUP($F3,FiveParts!$A$3:$B$33,2,FALSE) -> A5
A4: Total | B4: 0.10496 | C4: 0.11013 | D4: 528430 | E4: 1 | F4: 1 | G4: =VLOOKUP($F4,FiveParts!$A$3:$B$33,2,FALSE) -> A1
A5: Total | B5: 0.10215 | C5: 0.11253 | D5: 527010 | E5: 1 | F5: 4 | G5: =VLOOKUP($F5,FiveParts!$A$3:$B$33,2,FALSE) -> A4
A6: Total | B6: 0.014912 | C6: 0.017759 | D6: 583290 | E6: 1 | F6: 2 | G6: =VLOOKUP($F6,FiveParts!$A$3:$B$33,2,FALSE) -> A2
A7: Total | B7: 0.31329 | C7: 0.3252 | D7: 400720 | E7: 2 | F7: 1,3 | G7: =VLOOKUP($F7,FiveParts!$A$3:$B$33,2,FALSE) -> A7
A8: Total | B8: 0.30761 | C8: 0.32362 | D8: 401660 | E8: 2 | F8: 3,5 | G8: =VLOOKUP($F8,FiveParts!$A$3:$B$33,2,FALSE) -> A14
A9: Total | B9: 0.27195 | C9: 0.28879 | D9: 422340 | E9: 2 | F9: 3,4 | G9: =VLOOKUP($F9,FiveParts!$A$3:$B$33,2,FALSE) -> A13
A10: Total | B10: 0.23213 | C10: 0.24988 | D10: 445440 | E10: 2 | F10: 4,5 | G10: =VLOOKUP($F10,FiveParts!$A$3:$B$33,2,FALSE) -> A15
A11: Total | B11: 0.21074 | C11: 0.22442 | D11: 460560 | E11: 2 | F11: 1,4 | G11: =VLOOKUP($F11,FiveParts!$A$3:$B$33,2,FALSE) -> A8
A12: Total | B12: 0.19363 | C12: 0.20761 | D12: 470550 | E12: 2 | F12: 1,5 | G12: =VLOOKUP($F12,FiveParts!$A$3:$B$33,2,FALSE) -> A9
A13: Total | B13: 0.18751 | C13: 0.19926 | D13: 475510 | E13: 2 | F13: 2,3 | G13: =VLOOKUP($F13,FiveParts!$A$3:$B$33,2,FALSE) -> A10
A14: Total | B14: 0.12328 | C14: 0.13595 | D14: 513100 | E14: 2 | F14: 2,5 | G14: =VLOOKUP($F14,FiveParts!$A$3:$B$33,2,FALSE) -> A12
A15: Total | B15: 0.11971 | C15: 0.12735 | D15: 518210 | E15: 2 | F15: 1,2 | G15: =VLOOKUP($F15,FiveParts!$A$3:$B$33,2,FALSE) -> A6
A16: Total | B16: 0.11564 | C16: 0.12842 | D16: 517570 | E16: 2 | F16: 2,4 | G16: =VLOOKUP($F16,FiveParts!$A$3:$B$33,2,FALSE) -> A11
A17: Total | B17: 0.3886 | C17: 0.40627 | D17: 352580 | E17: 3 | F17: 1,3,5 | G17: =VLOOKUP($F17,FiveParts!$A$3:$B$33,2,FALSE) -> A20
A18: Total | B18: 0.36815 | C18: 0.39006 | D18: 362200 | E18: 3 | F18: 3,4,5 | G18: =VLOOKUP($F18,FiveParts!$A$3:$B$33,2,FALSE) -> A25
... A32: Total | B32: 0.44327 | C32: 0.4674 | D32: 316270 | E32: 5 | F32: 1,2,3,4,5 | G32: =VLOOKUP($F32,FiveParts!$A$3:$B$33,2,FALSE) -> A31
A33: Success | B33: 0.1357 | C33: 0.147 | D33: 590360 | E33: 1 | F33: 3 | G33: =VLOOKUP($F33,FiveParts!$A$3:$B$33,2,FALSE) -> A3
A34: Success | B34: 0.090416 | C34: 0.096361 | D34: 625410 | E34: 1 | F34: 1 | G34: =VLOOKUP($F34,FiveParts!$A$3:$B$33,2,FALSE) -> A1
A35: Success | B35: 0.087974 | C35: 0.10586 | D35: 618840 | E35: 1 | F35: 5 | G35: =VLOOKUP($F35,FiveParts!$A$3:$B$33,2,FALSE) -> A5
A36: Success | B36: 0.079055 | C36: 0.091093 | D36: 629050 | E36: 1 | F36: 4 | G36: =VLOOKUP($F36,FiveParts!$A$3:$B$33,2,FALSE) -> A4
A37: Success | B37: 0.017977 | C37: 0.021186 | D37: 677440 | E37: 1 | F37: 2 | G37: =VLOOKUP($F37,FiveParts!$A$3:$B$33,2,FALSE) -> A2
A38: Success | B38: 0.25221 | C38: 0.27665 | D38: 500630 | E38: 2 | F38: 3,5 | G38: =VLOOKUP($F38,FiveParts!$A$3:$B$33,2,FALSE) -> A14
A39: Success | B39: 0.24795 | C39: 0.26269 | D39: 510290 | E39: 2 | F39: 1,3 | G39: =VLOOKUP($F39,FiveParts!$A$3:$B$33,2,FALSE) -> A7
A40: Success | B40: 0.21243 | C40: 0.23302 | D40: 530820 | E40: 2 | F40: 3,4 | G40: =VLOOKUP($F40,FiveParts!$A$3:$B$33,2,FALSE) -> A13
A41: Success | B41: 0.19656 | C41: 0.22282 | D41: 537880 | E41: 2 | F41: 4,5 | G41: =VLOOKUP($F41,FiveParts!$A$3:$B$33,2,FALSE) -> A15
A42: Success | B42: 0.16896 | C42: 0.18526 | D42: 563880 | E42: 2 | F42: 1,4 | G42: =VLOOKUP($F42,FiveParts!$A$3:$B$33,2,FALSE) -> A8
A43: Success | B43: 0.15759 | C43: 0.17135 | D43: 573500 | E43: 2 | F43: 2,3 | G43: =VLOOKUP($F43,FiveParts!$A$3:$B$33,2,FALSE) -> A10
A44: Success | B44: 0.1566 | C44: 0.17865 | D44: 568460 | E44: 2 | F44: 1,5 | G44: =VLOOKUP($F44,FiveParts!$A$3:$B$33,2,FALSE) -> A9
A45: Success | B45: 0.099188 | C45: 0.10802 | D45: 617340 | E45: 2 | F45: 1,2 | G45: =VLOOKUP($F45,FiveParts!$A$3:$B$33,2,FALSE) -> A6
A46: Success | B46: 0.097626 | C46: 0.11237 | D46: 614330 | E46: 2 | F46: 2,4 | G46: =VLOOKUP($F46,FiveParts!$A$3:$B$33,2,FALSE) -> A11
A47: Success | B47: 0.094989 | C47: 0.11569 | D47: 612030 | E47: 2 | F47: 2,5 | G47: =VLOOKUP($F47,FiveParts!$A$3:$B$33,2,FALSE) -> A12
A48: Success | B48: 0.31086 | C48: 0.34239 | D48: 455130 | E48: 3 | F48: 3,4,5 | G48: =VLOOKUP($F48,FiveParts!$A$3:$B$33,2,FALSE) -> A25
A49: Success | B49: 0.30623 | C49: 0.33343 | D49: 461330 | E49: 3 | F49: 1,3,5 | G49: =VLOOKUP($F49,FiveParts!$A$3:$B$33,2,FALSE) -> A20
... A63: Success | B63: 0.37165 | C63: 0.40656 | D63: 410720 | E63: 5 | F63: 1,2,3,4,5 | G63: =VLOOKUP($F63,FiveParts!$A$3:$B$33,2,FALSE) -> A31
A64: Failure | B64: 0.14596 | C64: 0.15713 | D64: 600320 | E64: 1 | F64: 3 | G64: =VLOOKUP($F64,FiveParts!$A$3:$B$33,2,FALSE) -> A3
A65: Failure | B65: 0.066696 | C65: 0.072796 | D65: 660380 | E65: 1 | F65: 1 | G65: =VLOOKUP($F65,FiveParts!$A$3:$B$33,2,FALSE) -> A1
A66: Failure | B66: 0.058411 | C66: 0.070719 | D66: 661860 | E66: 1 | F66: 4 | G66: =VLOOKUP($F66,FiveParts!$A$3:$B$33,2,FALSE) -> A4
...

Sheet Notes
A1: Correlated Model | D1: Non-correlated Model
A2: 1 | B2: structural | D2: 1 | E2: spatial
A3: 2 | B3: environmental | D3: 2 | E3: temporal
A4: 3 | B4: anthropogenic | D4: 3 | E4: structural
A5: 4 | B5: spatial | D5: 4 | E5: environmental
A6: 5 | B6: temporal | D6: 5 | E6: anthropogenic
